2023-06-16 09:59:28,759 INFO    StreamThr :19292 [internal.py:wandb_internal():86] W&B internal server running at pid: 19292, started at: 2023-06-16 09:59:28.759861
2023-06-16 09:59:28,761 DEBUG   HandlerThread:19292 [handler.py:handle_request():144] handle_request: status
2023-06-16 09:59:28,884 INFO    WriterThread:19292 [datastore.py:open_for_write():85] open: C:\Users\WenqingLi\Documents\GitHub\deep-reinforcement-learning-\test_code\results\StarCraft2\academy_3_vs_1_with_keeper\mappo\check\wandb\run-20230616_095928-stwaqliw\run-stwaqliw.wandb
2023-06-16 09:59:28,885 DEBUG   SenderThread:19292 [sender.py:send():369] send: header
2023-06-16 09:59:29,027 DEBUG   SenderThread:19292 [sender.py:send():369] send: run
2023-06-16 09:59:30,337 ERROR   SenderThread:19292 [internal_api.py:execute():323] 403 response executing GraphQL.
2023-06-16 09:59:30,337 ERROR   SenderThread:19292 [internal_api.py:execute():324] {"errors":[{"message":"permission denied","path":["upsertBucket"],"extensions":{"code":"PERMISSION_ERROR"}}],"data":{"upsertBucket":null}}
2023-06-16 09:59:30,337 ERROR   SenderThread:19292 [sender.py:send_run():955] It appears that you do not have permission to access the requested resource. Please reach out to the project owner to grant you access. If you have the correct permissions, verify that there are no issues with your networking setup.(Error 403: Forbidden)
Traceback (most recent call last):
  File "C:\Users\WenqingLi\.conda\envs\torch\lib\site-packages\wandb\sdk\lib\retry.py", line 131, in __call__
    result = self._call_fn(*args, **kwargs)
  File "C:\Users\WenqingLi\.conda\envs\torch\lib\site-packages\wandb\sdk\internal\internal_api.py", line 320, in execute
    return self.client.execute(*args, **kwargs)  # type: ignore
  File "C:\Users\WenqingLi\.conda\envs\torch\lib\site-packages\wandb\vendor\gql-0.2.0\wandb_gql\client.py", line 52, in execute
    result = self._get_result(document, *args, **kwargs)
  File "C:\Users\WenqingLi\.conda\envs\torch\lib\site-packages\wandb\vendor\gql-0.2.0\wandb_gql\client.py", line 60, in _get_result
    return self.transport.execute(document, *args, **kwargs)
  File "C:\Users\WenqingLi\.conda\envs\torch\lib\site-packages\wandb\sdk\lib\gql_request.py", line 56, in execute
    request.raise_for_status()
  File "C:\Users\WenqingLi\.conda\envs\torch\lib\site-packages\requests\models.py", line 1021, in raise_for_status
    raise HTTPError(http_error_msg, response=self)
requests.exceptions.HTTPError: 403 Client Error: Forbidden for url: https://api.wandb.ai/graphql

During handling of the above exception, another exception occurred:

Traceback (most recent call last):
  File "C:\Users\WenqingLi\.conda\envs\torch\lib\site-packages\wandb\sdk\internal\sender.py", line 953, in send_run
    self._init_run(run, config_value_dict)
  File "C:\Users\WenqingLi\.conda\envs\torch\lib\site-packages\wandb\sdk\internal\sender.py", line 991, in _init_run
    server_run, inserted, server_messages = self._api.upsert_run(
  File "C:\Users\WenqingLi\.conda\envs\torch\lib\site-packages\wandb\apis\normalize.py", line 73, in wrapper
    raise err
  File "C:\Users\WenqingLi\.conda\envs\torch\lib\site-packages\wandb\apis\normalize.py", line 41, in wrapper
    return func(*args, **kwargs)
  File "C:\Users\WenqingLi\.conda\envs\torch\lib\site-packages\wandb\sdk\internal\internal_api.py", line 1727, in upsert_run
    response = self.gql(
  File "C:\Users\WenqingLi\.conda\envs\torch\lib\site-packages\wandb\sdk\internal\internal_api.py", line 292, in gql
    ret = self._retry_gql(
  File "C:\Users\WenqingLi\.conda\envs\torch\lib\site-packages\wandb\sdk\lib\retry.py", line 147, in __call__
    retry_timedelta_triggered = check_retry_fn(e)
  File "C:\Users\WenqingLi\.conda\envs\torch\lib\site-packages\wandb\util.py", line 908, in check_retry_fn
    return fallback_retry_fn(e)
  File "C:\Users\WenqingLi\.conda\envs\torch\lib\site-packages\wandb\util.py", line 850, in no_retry_auth
    raise CommError(
wandb.errors.CommError: It appears that you do not have permission to access the requested resource. Please reach out to the project owner to grant you access. If you have the correct permissions, verify that there are no issues with your networking setup.(Error 403: Forbidden)
2023-06-16 09:59:31,294 DEBUG   HandlerThread:19292 [handler.py:handle_request():144] handle_request: shutdown
2023-06-16 09:59:31,295 INFO    HandlerThread:19292 [handler.py:finish():854] shutting down handler
2023-06-16 09:59:31,346 INFO    SenderThread:19292 [sender.py:finish():1526] shutting down sender
2023-06-16 09:59:32,047 INFO    WriterThread:19292 [datastore.py:close():298] close: C:\Users\WenqingLi\Documents\GitHub\deep-reinforcement-learning-\test_code\results\StarCraft2\academy_3_vs_1_with_keeper\mappo\check\wandb\run-20230616_095928-stwaqliw\run-stwaqliw.wandb
